---
title: "Postupy: zpracování výjimky pomocí try-try catch (C# Průvodce programováním)"
ms.date: 07/20/2015
ms.prod: .net
ms.technology: devlang-csharp
ms.topic: article
helpviewer_keywords:
- exception handling [C#], try/catch blocks
- exceptions [C#], try/catch blocks
- try/catch blocks [C#]
ms.assetid: ca8e3773-980e-4767-8633-7408540e9818
caps.latest.revision: "14"
author: BillWagner
ms.author: wiwagn
ms.openlocfilehash: 9098bbcf5cefb85211f9d3bb9cac15943ba02172
ms.sourcegitcommit: 4f3fef493080a43e70e951223894768d36ce430a
ms.translationtype: MT
ms.contentlocale: cs-CZ
ms.lasthandoff: 11/21/2017
---
# <a name="how-to-handle-an-exception-using-trycatch-c-programming-guide"></a><span data-ttu-id="49aac-102">Postupy: Zpracování výjimky pomocí bloku try/catch (Průvodce programováním v C#)</span><span class="sxs-lookup"><span data-stu-id="49aac-102">How to: Handle an Exception Using try/catch (C# Programming Guide)</span></span>
<span data-ttu-id="49aac-103">Účel [try-catch –](../../../csharp/language-reference/keywords/try-catch.md) je blok catch a zpracování výjimky generované funkční kód.</span><span class="sxs-lookup"><span data-stu-id="49aac-103">The purpose of a [try-catch](../../../csharp/language-reference/keywords/try-catch.md) block is to catch and handle an exception generated by working code.</span></span> <span data-ttu-id="49aac-104">Některé výjimky lze zpracovat v `catch` bloku a problém vyřešit, bez výjimky se znovu; častěji jediné, co musíte se ale ujistěte se, že je vyvolána příslušné výjimky.</span><span class="sxs-lookup"><span data-stu-id="49aac-104">Some exceptions can be handled in a `catch` block and the problem solved without the exception being re-thrown; however, more often the only thing that you can do is make sure that the appropriate exception is thrown.</span></span>  
  
## <a name="example"></a><span data-ttu-id="49aac-105">Příklad</span><span class="sxs-lookup"><span data-stu-id="49aac-105">Example</span></span>  
 <span data-ttu-id="49aac-106">V tomto příkladu <xref:System.IndexOutOfRangeException> není nejvhodnější výjimka: <xref:System.ArgumentOutOfRangeException> větší smysl pro metodu vzhledem k tomu, že je chyba způsobená pomocí `index` argument předaná volající funkcí.</span><span class="sxs-lookup"><span data-stu-id="49aac-106">In this example, <xref:System.IndexOutOfRangeException> is not the most appropriate exception: <xref:System.ArgumentOutOfRangeException> makes more sense for the method because the error is caused by the `index` argument passed in by the caller.</span></span>  
  
 [!code-csharp[csProgGuideExceptions#5](../../../csharp/programming-guide/exceptions/codesnippet/CSharp/how-to-handle-an-exception-using-try-catch_1.cs)]  
  
## <a name="comments"></a><span data-ttu-id="49aac-107">Komentáře</span><span class="sxs-lookup"><span data-stu-id="49aac-107">Comments</span></span>  
 <span data-ttu-id="49aac-108">Kód, který způsobí výjimku ohraničeno `try` bloku.</span><span class="sxs-lookup"><span data-stu-id="49aac-108">The code that causes an exception is enclosed in the `try` block.</span></span> <span data-ttu-id="49aac-109">A `catch` je přidán příkaz ihned po zpracování `IndexOutOfRangeException`, pokud k němu dojde.</span><span class="sxs-lookup"><span data-stu-id="49aac-109">A `catch` statement is added immediately after to handle `IndexOutOfRangeException`, if it occurs.</span></span> <span data-ttu-id="49aac-110">`catch` Blokovat obslužné rutiny `IndexOutOfRangeException` a vyvolá vhodnější `ArgumentOutOfRangeException` výjimka místo.</span><span class="sxs-lookup"><span data-stu-id="49aac-110">The `catch` block handles the `IndexOutOfRangeException` and throws the more appropriate `ArgumentOutOfRangeException` exception instead.</span></span> <span data-ttu-id="49aac-111">Aby bylo možné poskytnout volající co nejvíce informací, zvažte zadání původní výjimka jako <xref:System.Exception.InnerException%2A> nové výjimky.</span><span class="sxs-lookup"><span data-stu-id="49aac-111">In order to provide the caller with as much information as possible, consider specifying the original exception as the <xref:System.Exception.InnerException%2A> of the new exception.</span></span> <span data-ttu-id="49aac-112">Protože <xref:System.Exception.InnerException%2A> vlastnost je [jen pro čtení](../../../csharp/language-reference/keywords/readonly.md), je nutné přiřadit v konstruktoru novou výjimku.</span><span class="sxs-lookup"><span data-stu-id="49aac-112">Because the <xref:System.Exception.InnerException%2A> property is [readonly](../../../csharp/language-reference/keywords/readonly.md), you must assign it in the constructor of the new exception.</span></span>  
  
## <a name="see-also"></a><span data-ttu-id="49aac-113">Viz také</span><span class="sxs-lookup"><span data-stu-id="49aac-113">See Also</span></span>  
 [<span data-ttu-id="49aac-114">Průvodce programováním v C#</span><span class="sxs-lookup"><span data-stu-id="49aac-114">C# Programming Guide</span></span>](../../../csharp/programming-guide/index.md)  
 [<span data-ttu-id="49aac-115">Výjimky a jejich zpracování</span><span class="sxs-lookup"><span data-stu-id="49aac-115">Exceptions and Exception Handling</span></span>](../../../csharp/programming-guide/exceptions/index.md)  
 [<span data-ttu-id="49aac-116">Zpracování výjimek</span><span class="sxs-lookup"><span data-stu-id="49aac-116">Exception Handling</span></span>](../../../csharp/programming-guide/exceptions/exception-handling.md)
