---
title: 'Postupy: zpracování výjimky pomocí bloku try-catch (C# Programming Guide)'
ms.date: 07/20/2015
helpviewer_keywords:
- exception handling [C#], try/catch blocks
- exceptions [C#], try/catch blocks
- try/catch blocks [C#]
ms.assetid: ca8e3773-980e-4767-8633-7408540e9818
ms.openlocfilehash: 74503c510007b132a7bbb14da7eade4c379b2179
ms.sourcegitcommit: 3c1c3ba79895335ff3737934e39372555ca7d6d0
ms.translationtype: MT
ms.contentlocale: cs-CZ
ms.lasthandoff: 09/06/2018
ms.locfileid: "43856573"
---
# <a name="how-to-handle-an-exception-using-trycatch-c-programming-guide"></a><span data-ttu-id="f5cfe-102">Postupy: Zpracování výjimky pomocí bloku try/catch (Průvodce programováním v C#)</span><span class="sxs-lookup"><span data-stu-id="f5cfe-102">How to: Handle an Exception Using try/catch (C# Programming Guide)</span></span>
<span data-ttu-id="f5cfe-103">Účel [bloku try-catch](../../../csharp/language-reference/keywords/try-catch.md) blok je k zachycení a zpracování výjimky generované funkční kód.</span><span class="sxs-lookup"><span data-stu-id="f5cfe-103">The purpose of a [try-catch](../../../csharp/language-reference/keywords/try-catch.md) block is to catch and handle an exception generated by working code.</span></span> <span data-ttu-id="f5cfe-104">Některé výjimky mohou být zpracovány v `catch` bloku a tento problém vyřešit bez výjimky je znovu vyvolána; však častěji pouze jednu, která vám pomůžou se ujistěte, že je vyvolána vhodná výjimka.</span><span class="sxs-lookup"><span data-stu-id="f5cfe-104">Some exceptions can be handled in a `catch` block and the problem solved without the exception being re-thrown; however, more often the only thing that you can do is make sure that the appropriate exception is thrown.</span></span>  
  
## <a name="example"></a><span data-ttu-id="f5cfe-105">Příklad</span><span class="sxs-lookup"><span data-stu-id="f5cfe-105">Example</span></span>  
 <span data-ttu-id="f5cfe-106">V tomto příkladu <xref:System.IndexOutOfRangeException> není nejvhodnější výjimka: <xref:System.ArgumentOutOfRangeException> větší smysl metoda vzhledem k tomu, chyba je způsobená `index` argument předaná volající funkcí.</span><span class="sxs-lookup"><span data-stu-id="f5cfe-106">In this example, <xref:System.IndexOutOfRangeException> is not the most appropriate exception: <xref:System.ArgumentOutOfRangeException> makes more sense for the method because the error is caused by the `index` argument passed in by the caller.</span></span>  
  
 [!code-csharp[csProgGuideExceptions#5](../../../csharp/programming-guide/exceptions/codesnippet/CSharp/how-to-handle-an-exception-using-try-catch_1.cs)]  
  
## <a name="comments"></a><span data-ttu-id="f5cfe-107">Komentáře</span><span class="sxs-lookup"><span data-stu-id="f5cfe-107">Comments</span></span>  
 <span data-ttu-id="f5cfe-108">Kód, který způsobí, že výjimka je ohraničen `try` bloku.</span><span class="sxs-lookup"><span data-stu-id="f5cfe-108">The code that causes an exception is enclosed in the `try` block.</span></span> <span data-ttu-id="f5cfe-109">A `catch` přidán příkaz ihned po zpracování `IndexOutOfRangeException`, pokud k němu dojde.</span><span class="sxs-lookup"><span data-stu-id="f5cfe-109">A `catch` statement is added immediately after to handle `IndexOutOfRangeException`, if it occurs.</span></span> <span data-ttu-id="f5cfe-110">`catch` Blokovat obslužné rutiny `IndexOutOfRangeException` a vyvolá více odpovídající `ArgumentOutOfRangeException` výjimka místo.</span><span class="sxs-lookup"><span data-stu-id="f5cfe-110">The `catch` block handles the `IndexOutOfRangeException` and throws the more appropriate `ArgumentOutOfRangeException` exception instead.</span></span> <span data-ttu-id="f5cfe-111">Aby bylo možné poskytnout co nejvíce informací volajícího, zvažte zadání původní výjimku jako <xref:System.Exception.InnerException%2A> nové výjimky.</span><span class="sxs-lookup"><span data-stu-id="f5cfe-111">In order to provide the caller with as much information as possible, consider specifying the original exception as the <xref:System.Exception.InnerException%2A> of the new exception.</span></span> <span data-ttu-id="f5cfe-112">Vzhledem k tomu, <xref:System.Exception.InnerException%2A> vlastnost je [jen pro čtení](../../../csharp/language-reference/keywords/readonly.md), je nutné přiřadit v konstruktoru novou výjimku.</span><span class="sxs-lookup"><span data-stu-id="f5cfe-112">Because the <xref:System.Exception.InnerException%2A> property is [readonly](../../../csharp/language-reference/keywords/readonly.md), you must assign it in the constructor of the new exception.</span></span>  
  
## <a name="see-also"></a><span data-ttu-id="f5cfe-113">Viz také</span><span class="sxs-lookup"><span data-stu-id="f5cfe-113">See Also</span></span>

- [<span data-ttu-id="f5cfe-114">Průvodce programováním v jazyce C#</span><span class="sxs-lookup"><span data-stu-id="f5cfe-114">C# Programming Guide</span></span>](../../../csharp/programming-guide/index.md)  
- [<span data-ttu-id="f5cfe-115">Výjimky a jejich zpracování</span><span class="sxs-lookup"><span data-stu-id="f5cfe-115">Exceptions and Exception Handling</span></span>](../../../csharp/programming-guide/exceptions/index.md)  
- [<span data-ttu-id="f5cfe-116">Zpracování výjimek</span><span class="sxs-lookup"><span data-stu-id="f5cfe-116">Exception Handling</span></span>](../../../csharp/programming-guide/exceptions/exception-handling.md)
